[2024-02-09T10:59:27.125+0000] {taskinstance.py:1956} INFO - Dependencies all met for dep_context=non-requeueable deps ti=<TaskInstance: Weather_DAG_V2.data_to_db scheduled__2024-02-09T01:46:00+00:00 [queued]>
[2024-02-09T10:59:27.356+0000] {taskinstance.py:1956} INFO - Dependencies all met for dep_context=requeueable deps ti=<TaskInstance: Weather_DAG_V2.data_to_db scheduled__2024-02-09T01:46:00+00:00 [queued]>
[2024-02-09T10:59:27.376+0000] {taskinstance.py:2170} INFO - Starting attempt 1 of 2
[2024-02-09T10:59:27.512+0000] {taskinstance.py:2191} INFO - Executing <Task(PythonOperator): data_to_db> on 2024-02-09 01:46:00+00:00
[2024-02-09T10:59:27.541+0000] {standard_task_runner.py:60} INFO - Started process 6245 to run task
[2024-02-09T10:59:27.625+0000] {standard_task_runner.py:87} INFO - Running: ['***', 'tasks', 'run', 'Weather_DAG_V2', 'data_to_db', 'scheduled__2024-02-09T01:46:00+00:00', '--job-id', '2267', '--raw', '--subdir', 'DAGS_FOLDER/Weather_dag.py', '--cfg-path', '/tmp/tmpvtv19ceg']
[2024-02-09T10:59:27.723+0000] {standard_task_runner.py:88} INFO - Job 2267: Subtask data_to_db
[2024-02-09T10:59:28.212+0000] {task_command.py:423} INFO - Running <TaskInstance: Weather_DAG_V2.data_to_db scheduled__2024-02-09T01:46:00+00:00 [running]> on host 06573eafe810
[2024-02-09T10:59:29.191+0000] {taskinstance.py:2480} INFO - Exporting env vars: AIRFLOW_CTX_DAG_OWNER='***' AIRFLOW_CTX_DAG_ID='Weather_DAG_V2' AIRFLOW_CTX_TASK_ID='data_to_db' AIRFLOW_CTX_EXECUTION_DATE='2024-02-09T01:46:00+00:00' AIRFLOW_CTX_TRY_NUMBER='1' AIRFLOW_CTX_DAG_RUN_ID='scheduled__2024-02-09T01:46:00+00:00'
[2024-02-09T10:59:29.223+0000] {taskinstance.py:2698} ERROR - Task failed with exception
Traceback (most recent call last):
  File "/home/airflow/.local/lib/python3.8/site-packages/airflow/models/taskinstance.py", line 433, in _execute_task
    result = execute_callable(context=context, **execute_callable_kwargs)
  File "/home/airflow/.local/lib/python3.8/site-packages/airflow/operators/python.py", line 199, in execute
    return_value = self.execute_callable()
  File "/home/airflow/.local/lib/python3.8/site-packages/airflow/operators/python.py", line 216, in execute_callable
    return self.python_callable(*self.op_args, **self.op_kwargs)
  File "/opt/airflow/dags/Weather_dag.py", line 72, in csv_db
    PostgresHook.bulk_load(table=weather_tab, tmp_file=CSV_DATA)
NameError: name 'weather_tab' is not defined
[2024-02-09T10:59:29.280+0000] {taskinstance.py:1138} INFO - Marking task as UP_FOR_RETRY. dag_id=Weather_DAG_V2, task_id=data_to_db, execution_date=20240209T014600, start_date=20240209T105927, end_date=20240209T105929
[2024-02-09T10:59:29.343+0000] {standard_task_runner.py:107} ERROR - Failed to execute job 2267 for task data_to_db (name 'weather_tab' is not defined; 6245)
[2024-02-09T10:59:29.389+0000] {local_task_job_runner.py:234} INFO - Task exited with return code 1
[2024-02-09T10:59:29.440+0000] {taskinstance.py:3280} INFO - 0 downstream tasks scheduled from follow-on schedule check
