[2024-02-12T08:57:54.350+0000] {taskinstance.py:1956} INFO - Dependencies all met for dep_context=non-requeueable deps ti=<TaskInstance: Weather_DAG_V3.9.data_to_db scheduled__2024-02-12T00:36:00+00:00 [queued]>
[2024-02-12T08:57:54.445+0000] {taskinstance.py:1956} INFO - Dependencies all met for dep_context=requeueable deps ti=<TaskInstance: Weather_DAG_V3.9.data_to_db scheduled__2024-02-12T00:36:00+00:00 [queued]>
[2024-02-12T08:57:54.451+0000] {taskinstance.py:2170} INFO - Starting attempt 1 of 1
[2024-02-12T08:57:54.522+0000] {taskinstance.py:2191} INFO - Executing <Task(PythonOperator): data_to_db> on 2024-02-12 00:36:00+00:00
[2024-02-12T08:57:54.601+0000] {standard_task_runner.py:60} INFO - Started process 2321 to run task
[2024-02-12T08:57:54.617+0000] {standard_task_runner.py:87} INFO - Running: ['***', 'tasks', 'run', 'Weather_DAG_V3.9', 'data_to_db', 'scheduled__2024-02-12T00:36:00+00:00', '--job-id', '6242', '--raw', '--subdir', 'DAGS_FOLDER/Weather_dag.py', '--cfg-path', '/tmp/tmpgm1g66i7']
[2024-02-12T08:57:54.698+0000] {standard_task_runner.py:88} INFO - Job 6242: Subtask data_to_db
[2024-02-12T08:57:54.877+0000] {task_command.py:423} INFO - Running <TaskInstance: Weather_DAG_V3.9.data_to_db scheduled__2024-02-12T00:36:00+00:00 [running]> on host 06573eafe810
[2024-02-12T08:57:55.202+0000] {taskinstance.py:2480} INFO - Exporting env vars: AIRFLOW_CTX_DAG_OWNER='***' AIRFLOW_CTX_DAG_ID='Weather_DAG_V3.9' AIRFLOW_CTX_TASK_ID='data_to_db' AIRFLOW_CTX_EXECUTION_DATE='2024-02-12T00:36:00+00:00' AIRFLOW_CTX_TRY_NUMBER='1' AIRFLOW_CTX_DAG_RUN_ID='scheduled__2024-02-12T00:36:00+00:00'
[2024-02-12T08:57:55.216+0000] {taskinstance.py:2698} ERROR - Task failed with exception
Traceback (most recent call last):
  File "/home/airflow/.local/lib/python3.8/site-packages/airflow/models/taskinstance.py", line 433, in _execute_task
    result = execute_callable(context=context, **execute_callable_kwargs)
  File "/home/airflow/.local/lib/python3.8/site-packages/airflow/operators/python.py", line 199, in execute
    return_value = self.execute_callable()
  File "/home/airflow/.local/lib/python3.8/site-packages/airflow/operators/python.py", line 216, in execute_callable
    return self.python_callable(*self.op_args, **self.op_kwargs)
  File "/opt/airflow/dags/Weather_dag.py", line 73, in csv_db
    hook.bulk_load(tmp_file=file_name)
TypeError: bulk_load() missing 1 required positional argument: 'table'
[2024-02-12T08:57:55.245+0000] {taskinstance.py:1138} INFO - Marking task as FAILED. dag_id=Weather_DAG_V3.9, task_id=data_to_db, execution_date=20240212T003600, start_date=20240212T085754, end_date=20240212T085755
[2024-02-12T08:57:55.321+0000] {standard_task_runner.py:107} ERROR - Failed to execute job 6242 for task data_to_db (bulk_load() missing 1 required positional argument: 'table'; 2321)
[2024-02-12T08:57:55.378+0000] {local_task_job_runner.py:234} INFO - Task exited with return code 1
[2024-02-12T08:57:55.424+0000] {taskinstance.py:3280} INFO - 0 downstream tasks scheduled from follow-on schedule check
