[2024-02-09T10:26:44.050+0000] {taskinstance.py:1956} INFO - Dependencies all met for dep_context=non-requeueable deps ti=<TaskInstance: Weather_DAG_V2.data_to_db scheduled__2024-02-09T00:16:00+00:00 [queued]>
[2024-02-09T10:26:44.068+0000] {taskinstance.py:1956} INFO - Dependencies all met for dep_context=requeueable deps ti=<TaskInstance: Weather_DAG_V2.data_to_db scheduled__2024-02-09T00:16:00+00:00 [queued]>
[2024-02-09T10:26:44.069+0000] {taskinstance.py:2170} INFO - Starting attempt 2 of 2
[2024-02-09T10:26:44.102+0000] {taskinstance.py:2191} INFO - Executing <Task(PythonOperator): data_to_db> on 2024-02-09 00:16:00+00:00
[2024-02-09T10:26:44.130+0000] {standard_task_runner.py:60} INFO - Started process 5545 to run task
[2024-02-09T10:26:44.146+0000] {standard_task_runner.py:87} INFO - Running: ['***', 'tasks', 'run', 'Weather_DAG_V2', 'data_to_db', 'scheduled__2024-02-09T00:16:00+00:00', '--job-id', '2195', '--raw', '--subdir', 'DAGS_FOLDER/Weather_dag.py', '--cfg-path', '/tmp/tmp_ug1q06f']
[2024-02-09T10:26:44.149+0000] {standard_task_runner.py:88} INFO - Job 2195: Subtask data_to_db
[2024-02-09T10:26:44.266+0000] {task_command.py:423} INFO - Running <TaskInstance: Weather_DAG_V2.data_to_db scheduled__2024-02-09T00:16:00+00:00 [running]> on host 06573eafe810
[2024-02-09T10:26:44.433+0000] {taskinstance.py:2480} INFO - Exporting env vars: AIRFLOW_CTX_DAG_OWNER='***' AIRFLOW_CTX_DAG_ID='Weather_DAG_V2' AIRFLOW_CTX_TASK_ID='data_to_db' AIRFLOW_CTX_EXECUTION_DATE='2024-02-09T00:16:00+00:00' AIRFLOW_CTX_TRY_NUMBER='2' AIRFLOW_CTX_DAG_RUN_ID='scheduled__2024-02-09T00:16:00+00:00'
[2024-02-09T10:26:44.442+0000] {taskinstance.py:2698} ERROR - Task failed with exception
Traceback (most recent call last):
  File "/home/airflow/.local/lib/python3.8/site-packages/airflow/models/taskinstance.py", line 433, in _execute_task
    result = execute_callable(context=context, **execute_callable_kwargs)
  File "/home/airflow/.local/lib/python3.8/site-packages/airflow/operators/python.py", line 199, in execute
    return_value = self.execute_callable()
  File "/home/airflow/.local/lib/python3.8/site-packages/airflow/operators/python.py", line 216, in execute_callable
    return self.python_callable(*self.op_args, **self.op_kwargs)
  File "/opt/airflow/dags/Weather_dag.py", line 72, in csv_db
    PostgresHook.bulk_load(table=weather_tab, tmp_file=CSV_DATA)
NameError: name 'weather_tab' is not defined
[2024-02-09T10:26:44.468+0000] {taskinstance.py:1138} INFO - Marking task as FAILED. dag_id=Weather_DAG_V2, task_id=data_to_db, execution_date=20240209T001600, start_date=20240209T102644, end_date=20240209T102644
[2024-02-09T10:26:44.498+0000] {standard_task_runner.py:107} ERROR - Failed to execute job 2195 for task data_to_db (name 'weather_tab' is not defined; 5545)
[2024-02-09T10:26:44.530+0000] {local_task_job_runner.py:234} INFO - Task exited with return code 1
[2024-02-09T10:26:44.559+0000] {taskinstance.py:3280} INFO - 0 downstream tasks scheduled from follow-on schedule check
