[2024-02-06T13:56:14.587+0000] {taskinstance.py:1956} INFO - Dependencies all met for dep_context=non-requeueable deps ti=<TaskInstance: titanic_pivot.download_titanic_dataset manual__2024-02-06T13:42:44.870403+00:00 [queued]>
[2024-02-06T13:56:14.598+0000] {taskinstance.py:1956} INFO - Dependencies all met for dep_context=requeueable deps ti=<TaskInstance: titanic_pivot.download_titanic_dataset manual__2024-02-06T13:42:44.870403+00:00 [queued]>
[2024-02-06T13:56:14.599+0000] {taskinstance.py:2170} INFO - Starting attempt 6 of 6
[2024-02-06T13:56:14.620+0000] {taskinstance.py:2191} INFO - Executing <Task(PythonOperator): download_titanic_dataset> on 2024-02-06 13:42:44.870403+00:00
[2024-02-06T13:56:14.632+0000] {standard_task_runner.py:87} INFO - Running: ['***', 'tasks', 'run', 'titanic_pivot', 'download_titanic_dataset', 'manual__2024-02-06T13:42:44.870403+00:00', '--job-id', '12', '--raw', '--subdir', 'DAGS_FOLDER/first_dag.py', '--cfg-path', '/tmp/tmp5omqbl0h']
[2024-02-06T13:56:14.634+0000] {standard_task_runner.py:88} INFO - Job 12: Subtask download_titanic_dataset
[2024-02-06T13:56:14.628+0000] {standard_task_runner.py:60} INFO - Started process 577 to run task
[2024-02-06T13:56:14.690+0000] {task_command.py:423} INFO - Running <TaskInstance: titanic_pivot.download_titanic_dataset manual__2024-02-06T13:42:44.870403+00:00 [running]> on host 06573eafe810
[2024-02-06T13:56:14.795+0000] {taskinstance.py:2480} INFO - Exporting env vars: AIRFLOW_CTX_DAG_OWNER='***' AIRFLOW_CTX_DAG_ID='titanic_pivot' AIRFLOW_CTX_TASK_ID='download_titanic_dataset' AIRFLOW_CTX_EXECUTION_DATE='2024-02-06T13:42:44.870403+00:00' AIRFLOW_CTX_TRY_NUMBER='6' AIRFLOW_CTX_DAG_RUN_ID='manual__2024-02-06T13:42:44.870403+00:00'
[2024-02-06T13:56:15.586+0000] {taskinstance.py:2698} ERROR - Task failed with exception
Traceback (most recent call last):
  File "/home/airflow/.local/lib/python3.8/site-packages/airflow/models/taskinstance.py", line 433, in _execute_task
    result = execute_callable(context=context, **execute_callable_kwargs)
  File "/home/airflow/.local/lib/python3.8/site-packages/airflow/operators/python.py", line 199, in execute
    return_value = self.execute_callable()
  File "/home/airflow/.local/lib/python3.8/site-packages/airflow/operators/python.py", line 216, in execute_callable
    return self.python_callable(*self.op_args, **self.op_kwargs)
  File "/opt/airflow/dags/first_dag.py", line 23, in download_titanic_dataset
    with open(FILENAME, 'w', encoding='utf-8') as f:
NameError: name 'FILENAME' is not defined
[2024-02-06T13:56:15.600+0000] {taskinstance.py:1138} INFO - Marking task as FAILED. dag_id=titanic_pivot, task_id=download_titanic_dataset, execution_date=20240206T134244, start_date=20240206T135614, end_date=20240206T135615
[2024-02-06T13:56:15.613+0000] {standard_task_runner.py:107} ERROR - Failed to execute job 12 for task download_titanic_dataset (name 'FILENAME' is not defined; 577)
[2024-02-06T13:56:15.624+0000] {local_task_job_runner.py:234} INFO - Task exited with return code 1
[2024-02-06T13:56:15.644+0000] {taskinstance.py:3280} INFO - 0 downstream tasks scheduled from follow-on schedule check
