[2024-02-09T14:42:48.925+0000] {taskinstance.py:1956} INFO - Dependencies all met for dep_context=non-requeueable deps ti=<TaskInstance: Weather_DAG_V3.5.get_weather scheduled__2024-02-09T01:16:00+00:00 [queued]>
[2024-02-09T14:42:48.993+0000] {taskinstance.py:1956} INFO - Dependencies all met for dep_context=requeueable deps ti=<TaskInstance: Weather_DAG_V3.5.get_weather scheduled__2024-02-09T01:16:00+00:00 [queued]>
[2024-02-09T14:42:48.995+0000] {taskinstance.py:2170} INFO - Starting attempt 2 of 2
[2024-02-09T14:42:49.062+0000] {taskinstance.py:2191} INFO - Executing <Task(PythonOperator): get_weather> on 2024-02-09 01:16:00+00:00
[2024-02-09T14:42:49.073+0000] {standard_task_runner.py:60} INFO - Started process 20468 to run task
[2024-02-09T14:42:49.107+0000] {standard_task_runner.py:87} INFO - Running: ['***', 'tasks', 'run', 'Weather_DAG_V3.5', 'get_weather', 'scheduled__2024-02-09T01:16:00+00:00', '--job-id', '5937', '--raw', '--subdir', 'DAGS_FOLDER/Weather_dag.py', '--cfg-path', '/tmp/tmp6_7h2xuz']
[2024-02-09T14:42:49.115+0000] {standard_task_runner.py:88} INFO - Job 5937: Subtask get_weather
[2024-02-09T14:42:49.284+0000] {task_command.py:423} INFO - Running <TaskInstance: Weather_DAG_V3.5.get_weather scheduled__2024-02-09T01:16:00+00:00 [running]> on host 06573eafe810
[2024-02-09T14:42:49.488+0000] {taskinstance.py:2480} INFO - Exporting env vars: AIRFLOW_CTX_DAG_OWNER='***' AIRFLOW_CTX_DAG_ID='Weather_DAG_V3.5' AIRFLOW_CTX_TASK_ID='get_weather' AIRFLOW_CTX_EXECUTION_DATE='2024-02-09T01:16:00+00:00' AIRFLOW_CTX_TRY_NUMBER='2' AIRFLOW_CTX_DAG_RUN_ID='scheduled__2024-02-09T01:16:00+00:00'
[2024-02-09T14:42:49.734+0000] {taskinstance.py:2698} ERROR - Task failed with exception
Traceback (most recent call last):
  File "/home/airflow/.local/lib/python3.8/site-packages/airflow/models/taskinstance.py", line 433, in _execute_task
    result = execute_callable(context=context, **execute_callable_kwargs)
  File "/home/airflow/.local/lib/python3.8/site-packages/airflow/operators/python.py", line 199, in execute
    return_value = self.execute_callable()
  File "/home/airflow/.local/lib/python3.8/site-packages/airflow/operators/python.py", line 216, in execute_callable
    return self.python_callable(*self.op_args, **self.op_kwargs)
  File "/opt/airflow/dags/Weather_dag.py", line 45, in get_weather
    for i in range(len(weather_data['forecasts'])):
KeyError: 'forecasts'
[2024-02-09T14:42:49.746+0000] {taskinstance.py:1138} INFO - Marking task as FAILED. dag_id=Weather_DAG_V3.5, task_id=get_weather, execution_date=20240209T011600, start_date=20240209T144248, end_date=20240209T144249
[2024-02-09T14:42:49.762+0000] {standard_task_runner.py:107} ERROR - Failed to execute job 5937 for task get_weather ('forecasts'; 20468)
[2024-02-09T14:42:49.783+0000] {local_task_job_runner.py:234} INFO - Task exited with return code 1
[2024-02-09T14:42:49.808+0000] {taskinstance.py:3280} INFO - 0 downstream tasks scheduled from follow-on schedule check
