[2024-02-12T14:47:47.230+0000] {taskinstance.py:1956} INFO - Dependencies all met for dep_context=non-requeueable deps ti=<TaskInstance: Weather_DAG_V5.1.data_to_db scheduled__2024-02-12T03:56:00+00:00 [queued]>
[2024-02-12T14:47:47.293+0000] {taskinstance.py:1956} INFO - Dependencies all met for dep_context=requeueable deps ti=<TaskInstance: Weather_DAG_V5.1.data_to_db scheduled__2024-02-12T03:56:00+00:00 [queued]>
[2024-02-12T14:47:47.298+0000] {taskinstance.py:2170} INFO - Starting attempt 1 of 1
[2024-02-12T14:47:47.348+0000] {taskinstance.py:2191} INFO - Executing <Task(PythonOperator): data_to_db> on 2024-02-12 03:56:00+00:00
[2024-02-12T14:47:47.360+0000] {standard_task_runner.py:60} INFO - Started process 21231 to run task
[2024-02-12T14:47:47.385+0000] {standard_task_runner.py:87} INFO - Running: ['***', 'tasks', 'run', 'Weather_DAG_V5.1', 'data_to_db', 'scheduled__2024-02-12T03:56:00+00:00', '--job-id', '10915', '--raw', '--subdir', 'DAGS_FOLDER/Weather_dag.py', '--cfg-path', '/tmp/tmpzpgs2e_a']
[2024-02-12T14:47:47.391+0000] {standard_task_runner.py:88} INFO - Job 10915: Subtask data_to_db
[2024-02-12T14:47:47.517+0000] {task_command.py:423} INFO - Running <TaskInstance: Weather_DAG_V5.1.data_to_db scheduled__2024-02-12T03:56:00+00:00 [running]> on host 06573eafe810
[2024-02-12T14:47:47.708+0000] {taskinstance.py:2480} INFO - Exporting env vars: AIRFLOW_CTX_DAG_OWNER='***' AIRFLOW_CTX_DAG_ID='Weather_DAG_V5.1' AIRFLOW_CTX_TASK_ID='data_to_db' AIRFLOW_CTX_EXECUTION_DATE='2024-02-12T03:56:00+00:00' AIRFLOW_CTX_TRY_NUMBER='1' AIRFLOW_CTX_DAG_RUN_ID='scheduled__2024-02-12T03:56:00+00:00'
[2024-02-12T14:47:47.745+0000] {base.py:83} INFO - Using connection ID 'postgres_localhost' for task execution.
[2024-02-12T14:47:47.761+0000] {taskinstance.py:2698} ERROR - Task failed with exception
Traceback (most recent call last):
  File "/home/airflow/.local/lib/python3.8/site-packages/airflow/models/taskinstance.py", line 433, in _execute_task
    result = execute_callable(context=context, **execute_callable_kwargs)
  File "/home/airflow/.local/lib/python3.8/site-packages/airflow/operators/python.py", line 199, in execute
    return_value = self.execute_callable()
  File "/home/airflow/.local/lib/python3.8/site-packages/airflow/operators/python.py", line 216, in execute_callable
    return self.python_callable(*self.op_args, **self.op_kwargs)
  File "/opt/airflow/dags/Weather_dag.py", line 82, in csv_db
    cursor.execute(sql_script)
psycopg2.errors.UndefinedFile: could not open file "weather.csv" for reading: No such file or directory
HINT:  COPY FROM instructs the PostgreSQL server process to read a file. You may want a client-side facility such as psql's \copy.

[2024-02-12T14:47:47.781+0000] {taskinstance.py:1138} INFO - Marking task as FAILED. dag_id=Weather_DAG_V5.1, task_id=data_to_db, execution_date=20240212T035600, start_date=20240212T144747, end_date=20240212T144747
[2024-02-12T14:47:47.831+0000] {standard_task_runner.py:107} ERROR - Failed to execute job 10915 for task data_to_db (could not open file "weather.csv" for reading: No such file or directory
HINT:  COPY FROM instructs the PostgreSQL server process to read a file. You may want a client-side facility such as psql's \copy.
; 21231)
[2024-02-12T14:47:47.891+0000] {local_task_job_runner.py:234} INFO - Task exited with return code 1
[2024-02-12T14:47:47.917+0000] {taskinstance.py:3280} INFO - 0 downstream tasks scheduled from follow-on schedule check
