[2024-02-12T13:46:49.669+0000] {taskinstance.py:1956} INFO - Dependencies all met for dep_context=non-requeueable deps ti=<TaskInstance: Weather_DAG_V4.10.data_to_db scheduled__2024-02-12T01:06:00+00:00 [queued]>
[2024-02-12T13:46:49.681+0000] {taskinstance.py:1956} INFO - Dependencies all met for dep_context=requeueable deps ti=<TaskInstance: Weather_DAG_V4.10.data_to_db scheduled__2024-02-12T01:06:00+00:00 [queued]>
[2024-02-12T13:46:49.683+0000] {taskinstance.py:2170} INFO - Starting attempt 1 of 1
[2024-02-12T13:46:49.719+0000] {taskinstance.py:2191} INFO - Executing <Task(PythonOperator): data_to_db> on 2024-02-12 01:06:00+00:00
[2024-02-12T13:46:49.726+0000] {standard_task_runner.py:60} INFO - Started process 17604 to run task
[2024-02-12T13:46:49.734+0000] {standard_task_runner.py:87} INFO - Running: ['***', 'tasks', 'run', 'Weather_DAG_V4.10', 'data_to_db', 'scheduled__2024-02-12T01:06:00+00:00', '--job-id', '9998', '--raw', '--subdir', 'DAGS_FOLDER/Weather_dag.py', '--cfg-path', '/tmp/tmprd3o_vw_']
[2024-02-12T13:46:49.736+0000] {standard_task_runner.py:88} INFO - Job 9998: Subtask data_to_db
[2024-02-12T13:46:49.814+0000] {task_command.py:423} INFO - Running <TaskInstance: Weather_DAG_V4.10.data_to_db scheduled__2024-02-12T01:06:00+00:00 [running]> on host 06573eafe810
[2024-02-12T13:46:49.919+0000] {taskinstance.py:2480} INFO - Exporting env vars: AIRFLOW_CTX_DAG_OWNER='***' AIRFLOW_CTX_DAG_ID='Weather_DAG_V4.10' AIRFLOW_CTX_TASK_ID='data_to_db' AIRFLOW_CTX_EXECUTION_DATE='2024-02-12T01:06:00+00:00' AIRFLOW_CTX_TRY_NUMBER='1' AIRFLOW_CTX_DAG_RUN_ID='scheduled__2024-02-12T01:06:00+00:00'
[2024-02-12T13:46:49.928+0000] {taskinstance.py:2698} ERROR - Task failed with exception
Traceback (most recent call last):
  File "/home/airflow/.local/lib/python3.8/site-packages/airflow/models/taskinstance.py", line 433, in _execute_task
    result = execute_callable(context=context, **execute_callable_kwargs)
  File "/home/airflow/.local/lib/python3.8/site-packages/airflow/operators/python.py", line 199, in execute
    return_value = self.execute_callable()
  File "/home/airflow/.local/lib/python3.8/site-packages/airflow/operators/python.py", line 216, in execute_callable
    return self.python_callable(*self.op_args, **self.op_kwargs)
  File "/opt/airflow/dags/Weather_dag.py", line 73, in csv_db
    CSV_DATA = pd.read_csv(file_name, header=None, index_col=False, parse_dates=True)
  File "/home/airflow/.local/lib/python3.8/site-packages/pandas/io/parsers/readers.py", line 912, in read_csv
    return _read(filepath_or_buffer, kwds)
  File "/home/airflow/.local/lib/python3.8/site-packages/pandas/io/parsers/readers.py", line 577, in _read
    parser = TextFileReader(filepath_or_buffer, **kwds)
  File "/home/airflow/.local/lib/python3.8/site-packages/pandas/io/parsers/readers.py", line 1407, in __init__
    self._engine = self._make_engine(f, self.engine)
  File "/home/airflow/.local/lib/python3.8/site-packages/pandas/io/parsers/readers.py", line 1679, in _make_engine
    return mapping[engine](f, **self.options)
  File "/home/airflow/.local/lib/python3.8/site-packages/pandas/io/parsers/c_parser_wrapper.py", line 93, in __init__
    self._reader = parsers.TextReader(src, **kwds)
  File "pandas/_libs/parsers.pyx", line 557, in pandas._libs.parsers.TextReader.__cinit__
pandas.errors.EmptyDataError: No columns to parse from file
[2024-02-12T13:46:49.941+0000] {taskinstance.py:1138} INFO - Marking task as FAILED. dag_id=Weather_DAG_V4.10, task_id=data_to_db, execution_date=20240212T010600, start_date=20240212T134649, end_date=20240212T134649
[2024-02-12T13:46:49.955+0000] {standard_task_runner.py:107} ERROR - Failed to execute job 9998 for task data_to_db (No columns to parse from file; 17604)
[2024-02-12T13:46:49.997+0000] {local_task_job_runner.py:234} INFO - Task exited with return code 1
[2024-02-12T13:46:50.017+0000] {taskinstance.py:3280} INFO - 0 downstream tasks scheduled from follow-on schedule check
