[2024-02-09T11:06:05.799+0000] {taskinstance.py:1956} INFO - Dependencies all met for dep_context=non-requeueable deps ti=<TaskInstance: Weather_DAG_V3.data_to_db scheduled__2024-02-09T00:56:00+00:00 [queued]>
[2024-02-09T11:06:05.818+0000] {taskinstance.py:1956} INFO - Dependencies all met for dep_context=requeueable deps ti=<TaskInstance: Weather_DAG_V3.data_to_db scheduled__2024-02-09T00:56:00+00:00 [queued]>
[2024-02-09T11:06:05.819+0000] {taskinstance.py:2170} INFO - Starting attempt 1 of 2
[2024-02-09T11:06:05.852+0000] {taskinstance.py:2191} INFO - Executing <Task(PythonOperator): data_to_db> on 2024-02-09 00:56:00+00:00
[2024-02-09T11:06:05.864+0000] {standard_task_runner.py:60} INFO - Started process 7273 to run task
[2024-02-09T11:06:05.871+0000] {standard_task_runner.py:87} INFO - Running: ['***', 'tasks', 'run', 'Weather_DAG_V3', 'data_to_db', 'scheduled__2024-02-09T00:56:00+00:00', '--job-id', '2585', '--raw', '--subdir', 'DAGS_FOLDER/Weather_dag.py', '--cfg-path', '/tmp/tmp6y7l6eq9']
[2024-02-09T11:06:05.873+0000] {standard_task_runner.py:88} INFO - Job 2585: Subtask data_to_db
[2024-02-09T11:06:05.952+0000] {task_command.py:423} INFO - Running <TaskInstance: Weather_DAG_V3.data_to_db scheduled__2024-02-09T00:56:00+00:00 [running]> on host 06573eafe810
[2024-02-09T11:06:06.085+0000] {taskinstance.py:2480} INFO - Exporting env vars: AIRFLOW_CTX_DAG_OWNER='***' AIRFLOW_CTX_DAG_ID='Weather_DAG_V3' AIRFLOW_CTX_TASK_ID='data_to_db' AIRFLOW_CTX_EXECUTION_DATE='2024-02-09T00:56:00+00:00' AIRFLOW_CTX_TRY_NUMBER='1' AIRFLOW_CTX_DAG_RUN_ID='scheduled__2024-02-09T00:56:00+00:00'
[2024-02-09T11:06:06.102+0000] {taskinstance.py:2698} ERROR - Task failed with exception
Traceback (most recent call last):
  File "/home/airflow/.local/lib/python3.8/site-packages/airflow/models/taskinstance.py", line 433, in _execute_task
    result = execute_callable(context=context, **execute_callable_kwargs)
  File "/home/airflow/.local/lib/python3.8/site-packages/airflow/operators/python.py", line 199, in execute
    return_value = self.execute_callable()
  File "/home/airflow/.local/lib/python3.8/site-packages/airflow/operators/python.py", line 216, in execute_callable
    return self.python_callable(*self.op_args, **self.op_kwargs)
  File "/opt/airflow/dags/Weather_dag.py", line 72, in csv_db
    PostgresHook.bulk_load(table='weather_tab', tmp_file=CSV_DATA)
TypeError: bulk_load() missing 1 required positional argument: 'self'
[2024-02-09T11:06:06.122+0000] {taskinstance.py:1138} INFO - Marking task as UP_FOR_RETRY. dag_id=Weather_DAG_V3, task_id=data_to_db, execution_date=20240209T005600, start_date=20240209T110605, end_date=20240209T110606
[2024-02-09T11:06:06.147+0000] {standard_task_runner.py:107} ERROR - Failed to execute job 2585 for task data_to_db (bulk_load() missing 1 required positional argument: 'self'; 7273)
[2024-02-09T11:06:06.162+0000] {local_task_job_runner.py:234} INFO - Task exited with return code 1
[2024-02-09T11:06:06.181+0000] {taskinstance.py:3280} INFO - 0 downstream tasks scheduled from follow-on schedule check
