[2024-02-09T11:42:40.491+0000] {taskinstance.py:1956} INFO - Dependencies all met for dep_context=non-requeueable deps ti=<TaskInstance: Weather_DAG_V1.2.data_to_db scheduled__2024-02-09T00:26:00+00:00 [queued]>
[2024-02-09T11:42:40.517+0000] {taskinstance.py:1956} INFO - Dependencies all met for dep_context=requeueable deps ti=<TaskInstance: Weather_DAG_V1.2.data_to_db scheduled__2024-02-09T00:26:00+00:00 [queued]>
[2024-02-09T11:42:40.518+0000] {taskinstance.py:2170} INFO - Starting attempt 1 of 2
[2024-02-09T11:42:40.569+0000] {taskinstance.py:2191} INFO - Executing <Task(PythonOperator): data_to_db> on 2024-02-09 00:26:00+00:00
[2024-02-09T11:42:40.587+0000] {standard_task_runner.py:60} INFO - Started process 9296 to run task
[2024-02-09T11:42:40.614+0000] {standard_task_runner.py:87} INFO - Running: ['***', 'tasks', 'run', 'Weather_DAG_V1.2', 'data_to_db', 'scheduled__2024-02-09T00:26:00+00:00', '--job-id', '3074', '--raw', '--subdir', 'DAGS_FOLDER/Weather_dag.py', '--cfg-path', '/tmp/tmpcts3d_rq']
[2024-02-09T11:42:40.617+0000] {standard_task_runner.py:88} INFO - Job 3074: Subtask data_to_db
[2024-02-09T11:42:40.812+0000] {task_command.py:423} INFO - Running <TaskInstance: Weather_DAG_V1.2.data_to_db scheduled__2024-02-09T00:26:00+00:00 [running]> on host 06573eafe810
[2024-02-09T11:42:41.040+0000] {taskinstance.py:2480} INFO - Exporting env vars: AIRFLOW_CTX_DAG_OWNER='***' AIRFLOW_CTX_DAG_ID='Weather_DAG_V1.2' AIRFLOW_CTX_TASK_ID='data_to_db' AIRFLOW_CTX_EXECUTION_DATE='2024-02-09T00:26:00+00:00' AIRFLOW_CTX_TRY_NUMBER='1' AIRFLOW_CTX_DAG_RUN_ID='scheduled__2024-02-09T00:26:00+00:00'
[2024-02-09T11:42:41.070+0000] {base.py:83} INFO - Using connection ID 'postgres_localhost' for task execution.
[2024-02-09T11:42:41.110+0000] {taskinstance.py:2698} ERROR - Task failed with exception
Traceback (most recent call last):
  File "/home/airflow/.local/lib/python3.8/site-packages/airflow/models/taskinstance.py", line 433, in _execute_task
    result = execute_callable(context=context, **execute_callable_kwargs)
  File "/home/airflow/.local/lib/python3.8/site-packages/airflow/operators/python.py", line 199, in execute
    return_value = self.execute_callable()
  File "/home/airflow/.local/lib/python3.8/site-packages/airflow/operators/python.py", line 216, in execute_callable
    return self.python_callable(*self.op_args, **self.op_kwargs)
  File "/opt/airflow/dags/Weather_dag.py", line 71, in csv_db
    hook.insert_rows(table='weather_tab', rows=file_name)
  File "/home/airflow/.local/lib/python3.8/site-packages/airflow/providers/common/sql/hooks/sql.py", line 527, in insert_rows
    with closing(self.get_conn()) as conn:
  File "/home/airflow/.local/lib/python3.8/site-packages/airflow/providers/postgres/hooks/postgres.py", line 158, in get_conn
    self.conn = psycopg2.connect(**conn_args)
  File "/home/airflow/.local/lib/python3.8/site-packages/psycopg2/__init__.py", line 122, in connect
    conn = _connect(dsn, connection_factory=connection_factory, **kwasync)
psycopg2.OperationalError: connection to server at "host.docker.internal" (192.168.65.254), port 5432 failed: FATAL:  database "public" does not exist

[2024-02-09T11:42:41.148+0000] {taskinstance.py:1138} INFO - Marking task as UP_FOR_RETRY. dag_id=Weather_DAG_V1.2, task_id=data_to_db, execution_date=20240209T002600, start_date=20240209T114240, end_date=20240209T114241
[2024-02-09T11:42:41.224+0000] {standard_task_runner.py:107} ERROR - Failed to execute job 3074 for task data_to_db (connection to server at "host.docker.internal" (192.168.65.254), port 5432 failed: FATAL:  database "public" does not exist
; 9296)
[2024-02-09T11:42:41.250+0000] {local_task_job_runner.py:234} INFO - Task exited with return code 1
[2024-02-09T11:42:41.481+0000] {taskinstance.py:3280} INFO - 0 downstream tasks scheduled from follow-on schedule check
