[2024-02-13T10:29:56.249+0000] {taskinstance.py:1956} INFO - Dependencies all met for dep_context=non-requeueable deps ti=<TaskInstance: 1Training_DAG_V1.0.data_to_db manual__2024-02-13T10:29:49.144069+00:00 [queued]>
[2024-02-13T10:29:56.274+0000] {taskinstance.py:1956} INFO - Dependencies all met for dep_context=requeueable deps ti=<TaskInstance: 1Training_DAG_V1.0.data_to_db manual__2024-02-13T10:29:49.144069+00:00 [queued]>
[2024-02-13T10:29:56.277+0000] {taskinstance.py:2170} INFO - Starting attempt 1 of 1
[2024-02-13T10:29:56.357+0000] {taskinstance.py:2191} INFO - Executing <Task(PythonOperator): data_to_db> on 2024-02-13 10:29:49.144069+00:00
[2024-02-13T10:29:56.370+0000] {standard_task_runner.py:60} INFO - Started process 3076 to run task
[2024-02-13T10:29:56.375+0000] {standard_task_runner.py:87} INFO - Running: ['***', 'tasks', 'run', '1Training_DAG_V1.0', 'data_to_db', 'manual__2024-02-13T10:29:49.144069+00:00', '--job-id', '11265', '--raw', '--subdir', 'DAGS_FOLDER/traning_dag.py', '--cfg-path', '/tmp/tmp90e_pt1w']
[2024-02-13T10:29:56.386+0000] {standard_task_runner.py:88} INFO - Job 11265: Subtask data_to_db
[2024-02-13T10:29:56.535+0000] {task_command.py:423} INFO - Running <TaskInstance: 1Training_DAG_V1.0.data_to_db manual__2024-02-13T10:29:49.144069+00:00 [running]> on host 06573eafe810
[2024-02-13T10:29:56.706+0000] {taskinstance.py:2480} INFO - Exporting env vars: AIRFLOW_CTX_DAG_OWNER='***' AIRFLOW_CTX_DAG_ID='1Training_DAG_V1.0' AIRFLOW_CTX_TASK_ID='data_to_db' AIRFLOW_CTX_EXECUTION_DATE='2024-02-13T10:29:49.144069+00:00' AIRFLOW_CTX_TRY_NUMBER='1' AIRFLOW_CTX_DAG_RUN_ID='manual__2024-02-13T10:29:49.144069+00:00'
[2024-02-13T10:29:56.723+0000] {logging_mixin.py:188} INFO - Москва 2024-02-12 1
[2024-02-13T10:29:56.748+0000] {base.py:83} INFO - Using connection ID 'postgres_localhost' for task execution.
[2024-02-13T10:29:56.769+0000] {taskinstance.py:2698} ERROR - Task failed with exception
Traceback (most recent call last):
  File "/home/airflow/.local/lib/python3.8/site-packages/airflow/models/taskinstance.py", line 433, in _execute_task
    result = execute_callable(context=context, **execute_callable_kwargs)
  File "/home/airflow/.local/lib/python3.8/site-packages/airflow/operators/python.py", line 199, in execute
    return_value = self.execute_callable()
  File "/home/airflow/.local/lib/python3.8/site-packages/airflow/operators/python.py", line 216, in execute_callable
    return self.python_callable(*self.op_args, **self.op_kwargs)
  File "/opt/airflow/dags/traning_dag.py", line 31, in csv_db
    cursor.execute(sql_script)
psycopg2.errors.UndefinedTable: relation "Москва" does not exist
LINE 1: INSERT INTO Москва VALUES (Training(city))
                    ^

[2024-02-13T10:29:56.786+0000] {taskinstance.py:1138} INFO - Marking task as FAILED. dag_id=1Training_DAG_V1.0, task_id=data_to_db, execution_date=20240213T102949, start_date=20240213T102956, end_date=20240213T102956
[2024-02-13T10:29:56.809+0000] {standard_task_runner.py:107} ERROR - Failed to execute job 11265 for task data_to_db (relation "Москва" does not exist
LINE 1: INSERT INTO Москва VALUES (Training(city))
                    ^
; 3076)
[2024-02-13T10:29:56.863+0000] {local_task_job_runner.py:234} INFO - Task exited with return code 1
[2024-02-13T10:29:56.898+0000] {taskinstance.py:3280} INFO - 0 downstream tasks scheduled from follow-on schedule check
