[2024-02-12T08:56:06.155+0000] {taskinstance.py:1956} INFO - Dependencies all met for dep_context=non-requeueable deps ti=<TaskInstance: Weather_DAG_V3.8.data_to_db scheduled__2024-02-12T00:36:00+00:00 [queued]>
[2024-02-12T08:56:06.246+0000] {taskinstance.py:1956} INFO - Dependencies all met for dep_context=requeueable deps ti=<TaskInstance: Weather_DAG_V3.8.data_to_db scheduled__2024-02-12T00:36:00+00:00 [queued]>
[2024-02-12T08:56:06.258+0000] {taskinstance.py:2170} INFO - Starting attempt 1 of 1
[2024-02-12T08:56:06.414+0000] {taskinstance.py:2191} INFO - Executing <Task(PythonOperator): data_to_db> on 2024-02-12 00:36:00+00:00
[2024-02-12T08:56:06.460+0000] {standard_task_runner.py:60} INFO - Started process 1952 to run task
[2024-02-12T08:56:06.500+0000] {standard_task_runner.py:87} INFO - Running: ['***', 'tasks', 'run', 'Weather_DAG_V3.8', 'data_to_db', 'scheduled__2024-02-12T00:36:00+00:00', '--job-id', '6131', '--raw', '--subdir', 'DAGS_FOLDER/Weather_dag.py', '--cfg-path', '/tmp/tmpwwxrmyzv']
[2024-02-12T08:56:06.550+0000] {standard_task_runner.py:88} INFO - Job 6131: Subtask data_to_db
[2024-02-12T08:56:06.694+0000] {task_command.py:423} INFO - Running <TaskInstance: Weather_DAG_V3.8.data_to_db scheduled__2024-02-12T00:36:00+00:00 [running]> on host 06573eafe810
[2024-02-12T08:56:07.000+0000] {taskinstance.py:2480} INFO - Exporting env vars: AIRFLOW_CTX_DAG_OWNER='***' AIRFLOW_CTX_DAG_ID='Weather_DAG_V3.8' AIRFLOW_CTX_TASK_ID='data_to_db' AIRFLOW_CTX_EXECUTION_DATE='2024-02-12T00:36:00+00:00' AIRFLOW_CTX_TRY_NUMBER='1' AIRFLOW_CTX_DAG_RUN_ID='scheduled__2024-02-12T00:36:00+00:00'
[2024-02-12T08:56:07.009+0000] {taskinstance.py:2698} ERROR - Task failed with exception
Traceback (most recent call last):
  File "/home/airflow/.local/lib/python3.8/site-packages/airflow/models/taskinstance.py", line 433, in _execute_task
    result = execute_callable(context=context, **execute_callable_kwargs)
  File "/home/airflow/.local/lib/python3.8/site-packages/airflow/operators/python.py", line 199, in execute
    return_value = self.execute_callable()
  File "/home/airflow/.local/lib/python3.8/site-packages/airflow/operators/python.py", line 216, in execute_callable
    return self.python_callable(*self.op_args, **self.op_kwargs)
  File "/opt/airflow/dags/Weather_dag.py", line 73, in csv_db
    hook.bulk_load('weather_tab')
TypeError: bulk_load() missing 1 required positional argument: 'tmp_file'
[2024-02-12T08:56:07.042+0000] {taskinstance.py:1138} INFO - Marking task as FAILED. dag_id=Weather_DAG_V3.8, task_id=data_to_db, execution_date=20240212T003600, start_date=20240212T085606, end_date=20240212T085607
[2024-02-12T08:56:07.132+0000] {standard_task_runner.py:107} ERROR - Failed to execute job 6131 for task data_to_db (bulk_load() missing 1 required positional argument: 'tmp_file'; 1952)
[2024-02-12T08:56:07.169+0000] {local_task_job_runner.py:234} INFO - Task exited with return code 1
[2024-02-12T08:56:07.258+0000] {taskinstance.py:3280} INFO - 0 downstream tasks scheduled from follow-on schedule check
