[2024-02-09T14:16:19.715+0000] {taskinstance.py:1956} INFO - Dependencies all met for dep_context=non-requeueable deps ti=<TaskInstance: Weather_DAG_V3.1.data_to_db scheduled__2024-02-09T01:16:00+00:00 [queued]>
[2024-02-09T14:16:19.781+0000] {taskinstance.py:1956} INFO - Dependencies all met for dep_context=requeueable deps ti=<TaskInstance: Weather_DAG_V3.1.data_to_db scheduled__2024-02-09T01:16:00+00:00 [queued]>
[2024-02-09T14:16:19.782+0000] {taskinstance.py:2170} INFO - Starting attempt 2 of 2
[2024-02-09T14:16:19.845+0000] {taskinstance.py:2191} INFO - Executing <Task(PythonOperator): data_to_db> on 2024-02-09 01:16:00+00:00
[2024-02-09T14:16:19.877+0000] {standard_task_runner.py:60} INFO - Started process 18597 to run task
[2024-02-09T14:16:19.955+0000] {standard_task_runner.py:87} INFO - Running: ['***', 'tasks', 'run', 'Weather_DAG_V3.1', 'data_to_db', 'scheduled__2024-02-09T01:16:00+00:00', '--job-id', '5434', '--raw', '--subdir', 'DAGS_FOLDER/Weather_dag.py', '--cfg-path', '/tmp/tmp9i_zjrrp']
[2024-02-09T14:16:19.984+0000] {standard_task_runner.py:88} INFO - Job 5434: Subtask data_to_db
[2024-02-09T14:16:20.305+0000] {task_command.py:423} INFO - Running <TaskInstance: Weather_DAG_V3.1.data_to_db scheduled__2024-02-09T01:16:00+00:00 [running]> on host 06573eafe810
[2024-02-09T14:16:20.940+0000] {taskinstance.py:2480} INFO - Exporting env vars: AIRFLOW_CTX_DAG_OWNER='***' AIRFLOW_CTX_DAG_ID='Weather_DAG_V3.1' AIRFLOW_CTX_TASK_ID='data_to_db' AIRFLOW_CTX_EXECUTION_DATE='2024-02-09T01:16:00+00:00' AIRFLOW_CTX_TRY_NUMBER='2' AIRFLOW_CTX_DAG_RUN_ID='scheduled__2024-02-09T01:16:00+00:00'
[2024-02-09T14:16:20.991+0000] {taskinstance.py:2698} ERROR - Task failed with exception
Traceback (most recent call last):
  File "/home/airflow/.local/lib/python3.8/site-packages/airflow/models/taskinstance.py", line 433, in _execute_task
    result = execute_callable(context=context, **execute_callable_kwargs)
  File "/home/airflow/.local/lib/python3.8/site-packages/airflow/operators/python.py", line 199, in execute
    return_value = self.execute_callable()
  File "/home/airflow/.local/lib/python3.8/site-packages/airflow/operators/python.py", line 216, in execute_callable
    return self.python_callable(*self.op_args, **self.op_kwargs)
  File "/opt/airflow/dags/Weather_dag.py", line 72, in csv_db
    CSV_DATA.drop(columns=['Unnamed: 0'], inplace=True)
  File "/home/airflow/.local/lib/python3.8/site-packages/pandas/core/frame.py", line 5258, in drop
    return super().drop(
  File "/home/airflow/.local/lib/python3.8/site-packages/pandas/core/generic.py", line 4549, in drop
    obj = obj._drop_axis(labels, axis, level=level, errors=errors)
  File "/home/airflow/.local/lib/python3.8/site-packages/pandas/core/generic.py", line 4591, in _drop_axis
    new_axis = axis.drop(labels, errors=errors)
  File "/home/airflow/.local/lib/python3.8/site-packages/pandas/core/indexes/base.py", line 6699, in drop
    raise KeyError(f"{list(labels[mask])} not found in axis")
KeyError: "['Unnamed: 0'] not found in axis"
[2024-02-09T14:16:21.093+0000] {taskinstance.py:1138} INFO - Marking task as FAILED. dag_id=Weather_DAG_V3.1, task_id=data_to_db, execution_date=20240209T011600, start_date=20240209T141619, end_date=20240209T141621
[2024-02-09T14:16:21.230+0000] {standard_task_runner.py:107} ERROR - Failed to execute job 5434 for task data_to_db ("['Unnamed: 0'] not found in axis"; 18597)
[2024-02-09T14:16:21.443+0000] {local_task_job_runner.py:234} INFO - Task exited with return code 1
[2024-02-09T14:16:22.088+0000] {taskinstance.py:3280} INFO - 0 downstream tasks scheduled from follow-on schedule check
