[2024-02-09T13:49:06.366+0000] {taskinstance.py:1956} INFO - Dependencies all met for dep_context=non-requeueable deps ti=<TaskInstance: Weather_DAG_V2.7.data_to_db scheduled__2024-02-09T01:11:00+00:00 [queued]>
[2024-02-09T13:49:06.406+0000] {taskinstance.py:1956} INFO - Dependencies all met for dep_context=requeueable deps ti=<TaskInstance: Weather_DAG_V2.7.data_to_db scheduled__2024-02-09T01:11:00+00:00 [queued]>
[2024-02-09T13:49:06.407+0000] {taskinstance.py:2170} INFO - Starting attempt 1 of 2
[2024-02-09T13:49:06.465+0000] {taskinstance.py:2191} INFO - Executing <Task(PythonOperator): data_to_db> on 2024-02-09 01:11:00+00:00
[2024-02-09T13:49:06.475+0000] {standard_task_runner.py:60} INFO - Started process 16823 to run task
[2024-02-09T13:49:06.494+0000] {standard_task_runner.py:87} INFO - Running: ['***', 'tasks', 'run', 'Weather_DAG_V2.7', 'data_to_db', 'scheduled__2024-02-09T01:11:00+00:00', '--job-id', '4983', '--raw', '--subdir', 'DAGS_FOLDER/Weather_dag.py', '--cfg-path', '/tmp/tmpfl1ovja3']
[2024-02-09T13:49:06.505+0000] {standard_task_runner.py:88} INFO - Job 4983: Subtask data_to_db
[2024-02-09T13:49:06.652+0000] {task_command.py:423} INFO - Running <TaskInstance: Weather_DAG_V2.7.data_to_db scheduled__2024-02-09T01:11:00+00:00 [running]> on host 06573eafe810
[2024-02-09T13:49:06.908+0000] {taskinstance.py:2480} INFO - Exporting env vars: AIRFLOW_CTX_DAG_OWNER='***' AIRFLOW_CTX_DAG_ID='Weather_DAG_V2.7' AIRFLOW_CTX_TASK_ID='data_to_db' AIRFLOW_CTX_EXECUTION_DATE='2024-02-09T01:11:00+00:00' AIRFLOW_CTX_TRY_NUMBER='1' AIRFLOW_CTX_DAG_RUN_ID='scheduled__2024-02-09T01:11:00+00:00'
[2024-02-09T13:49:06.919+0000] {taskinstance.py:2698} ERROR - Task failed with exception
Traceback (most recent call last):
  File "/home/airflow/.local/lib/python3.8/site-packages/airflow/models/taskinstance.py", line 433, in _execute_task
    result = execute_callable(context=context, **execute_callable_kwargs)
  File "/home/airflow/.local/lib/python3.8/site-packages/airflow/operators/python.py", line 199, in execute
    return_value = self.execute_callable()
  File "/home/airflow/.local/lib/python3.8/site-packages/airflow/operators/python.py", line 216, in execute_callable
    return self.python_callable(*self.op_args, **self.op_kwargs)
  File "/opt/airflow/dags/Weather_dag.py", line 71, in csv_db
    CSV_DATA = pd.read_csv(file_name, sep=',', header=None, parse_dates=['date'])
  File "/home/airflow/.local/lib/python3.8/site-packages/pandas/io/parsers/readers.py", line 912, in read_csv
    return _read(filepath_or_buffer, kwds)
  File "/home/airflow/.local/lib/python3.8/site-packages/pandas/io/parsers/readers.py", line 577, in _read
    parser = TextFileReader(filepath_or_buffer, **kwds)
  File "/home/airflow/.local/lib/python3.8/site-packages/pandas/io/parsers/readers.py", line 1407, in __init__
    self._engine = self._make_engine(f, self.engine)
  File "/home/airflow/.local/lib/python3.8/site-packages/pandas/io/parsers/readers.py", line 1679, in _make_engine
    return mapping[engine](f, **self.options)
  File "/home/airflow/.local/lib/python3.8/site-packages/pandas/io/parsers/c_parser_wrapper.py", line 161, in __init__
    self._validate_parse_dates_presence(self.names)  # type: ignore[has-type]
  File "/home/airflow/.local/lib/python3.8/site-packages/pandas/io/parsers/base_parser.py", line 230, in _validate_parse_dates_presence
    raise ValueError(
ValueError: Missing column provided to 'parse_dates': 'date'
[2024-02-09T13:49:06.932+0000] {taskinstance.py:1138} INFO - Marking task as UP_FOR_RETRY. dag_id=Weather_DAG_V2.7, task_id=data_to_db, execution_date=20240209T011100, start_date=20240209T134906, end_date=20240209T134906
[2024-02-09T13:49:06.970+0000] {standard_task_runner.py:107} ERROR - Failed to execute job 4983 for task data_to_db (Missing column provided to 'parse_dates': 'date'; 16823)
[2024-02-09T13:49:07.034+0000] {local_task_job_runner.py:234} INFO - Task exited with return code 1
[2024-02-09T13:49:07.216+0000] {taskinstance.py:3280} INFO - 0 downstream tasks scheduled from follow-on schedule check
