[2024-02-12T10:33:56.392+0000] {taskinstance.py:1956} INFO - Dependencies all met for dep_context=non-requeueable deps ti=<TaskInstance: Weather_DAG_V3.16.data_to_db scheduled__2024-02-12T00:51:00+00:00 [queued]>
[2024-02-12T10:33:56.420+0000] {taskinstance.py:1956} INFO - Dependencies all met for dep_context=requeueable deps ti=<TaskInstance: Weather_DAG_V3.16.data_to_db scheduled__2024-02-12T00:51:00+00:00 [queued]>
[2024-02-12T10:33:56.421+0000] {taskinstance.py:2170} INFO - Starting attempt 1 of 1
[2024-02-12T10:33:56.538+0000] {taskinstance.py:2191} INFO - Executing <Task(PythonOperator): data_to_db> on 2024-02-12 00:51:00+00:00
[2024-02-12T10:33:56.576+0000] {standard_task_runner.py:60} INFO - Started process 6402 to run task
[2024-02-12T10:33:56.605+0000] {standard_task_runner.py:87} INFO - Running: ['***', 'tasks', 'run', 'Weather_DAG_V3.16', 'data_to_db', 'scheduled__2024-02-12T00:51:00+00:00', '--job-id', '7152', '--raw', '--subdir', 'DAGS_FOLDER/Weather_dag.py', '--cfg-path', '/tmp/tmp7i18s0_e']
[2024-02-12T10:33:56.620+0000] {standard_task_runner.py:88} INFO - Job 7152: Subtask data_to_db
[2024-02-12T10:33:56.946+0000] {task_command.py:423} INFO - Running <TaskInstance: Weather_DAG_V3.16.data_to_db scheduled__2024-02-12T00:51:00+00:00 [running]> on host 06573eafe810
[2024-02-12T10:33:57.190+0000] {taskinstance.py:2480} INFO - Exporting env vars: AIRFLOW_CTX_DAG_OWNER='***' AIRFLOW_CTX_DAG_ID='Weather_DAG_V3.16' AIRFLOW_CTX_TASK_ID='data_to_db' AIRFLOW_CTX_EXECUTION_DATE='2024-02-12T00:51:00+00:00' AIRFLOW_CTX_TRY_NUMBER='1' AIRFLOW_CTX_DAG_RUN_ID='scheduled__2024-02-12T00:51:00+00:00'
[2024-02-12T10:33:57.269+0000] {postgres.py:172} INFO - Running copy expert: COPY weather_tabb FROM STDIN, filename: weather.csv
[2024-02-12T10:33:57.310+0000] {base.py:83} INFO - Using connection ID 'postgres_localhost' for task execution.
[2024-02-12T10:33:57.372+0000] {taskinstance.py:2698} ERROR - Task failed with exception
Traceback (most recent call last):
  File "/home/airflow/.local/lib/python3.8/site-packages/airflow/models/taskinstance.py", line 433, in _execute_task
    result = execute_callable(context=context, **execute_callable_kwargs)
  File "/home/airflow/.local/lib/python3.8/site-packages/airflow/operators/python.py", line 199, in execute
    return_value = self.execute_callable()
  File "/home/airflow/.local/lib/python3.8/site-packages/airflow/operators/python.py", line 216, in execute_callable
    return self.python_callable(*self.op_args, **self.op_kwargs)
  File "/opt/airflow/dags/Weather_dag.py", line 76, in csv_db
    hook.bulk_load(tmp_file=file_name, table='weather_tabb')
  File "/home/airflow/.local/lib/python3.8/site-packages/airflow/providers/postgres/hooks/postgres.py", line 194, in bulk_load
    self.copy_expert(f"COPY {table} FROM STDIN", tmp_file)
  File "/home/airflow/.local/lib/python3.8/site-packages/airflow/providers/postgres/hooks/postgres.py", line 178, in copy_expert
    cur.copy_expert(sql, file)
psycopg2.errors.BadCopyFileFormat: missing data for column "dt"
CONTEXT:  COPY weather_tabb, line 1: ",0.0,1.0,2.0,3.0,4.0,5.0,6.0,7.0,8.0,9.0,10.0,11.0,12.0,13.0,14.0,15.0,16.0,17.0,18.0,19.0,20.0,21.0..."

[2024-02-12T10:33:57.406+0000] {taskinstance.py:1138} INFO - Marking task as FAILED. dag_id=Weather_DAG_V3.16, task_id=data_to_db, execution_date=20240212T005100, start_date=20240212T103356, end_date=20240212T103357
[2024-02-12T10:33:57.444+0000] {standard_task_runner.py:107} ERROR - Failed to execute job 7152 for task data_to_db (missing data for column "dt"
CONTEXT:  COPY weather_tabb, line 1: ",0.0,1.0,2.0,3.0,4.0,5.0,6.0,7.0,8.0,9.0,10.0,11.0,12.0,13.0,14.0,15.0,16.0,17.0,18.0,19.0,20.0,21.0..."
; 6402)
[2024-02-12T10:33:57.493+0000] {local_task_job_runner.py:234} INFO - Task exited with return code 1
[2024-02-12T10:33:57.532+0000] {taskinstance.py:3280} INFO - 0 downstream tasks scheduled from follow-on schedule check
