[2024-02-09T12:38:25.656+0000] {taskinstance.py:1956} INFO - Dependencies all met for dep_context=non-requeueable deps ti=<TaskInstance: Weather_DAG_V2.4.data_to_db scheduled__2024-02-09T01:56:00+00:00 [queued]>
[2024-02-09T12:38:25.710+0000] {taskinstance.py:1956} INFO - Dependencies all met for dep_context=requeueable deps ti=<TaskInstance: Weather_DAG_V2.4.data_to_db scheduled__2024-02-09T01:56:00+00:00 [queued]>
[2024-02-09T12:38:25.716+0000] {taskinstance.py:2170} INFO - Starting attempt 1 of 2
[2024-02-09T12:38:25.795+0000] {taskinstance.py:2191} INFO - Executing <Task(PythonOperator): data_to_db> on 2024-02-09 01:56:00+00:00
[2024-02-09T12:38:25.804+0000] {standard_task_runner.py:60} INFO - Started process 11415 to run task
[2024-02-09T12:38:25.826+0000] {standard_task_runner.py:87} INFO - Running: ['***', 'tasks', 'run', 'Weather_DAG_V2.4', 'data_to_db', 'scheduled__2024-02-09T01:56:00+00:00', '--job-id', '3509', '--raw', '--subdir', 'DAGS_FOLDER/Weather_dag.py', '--cfg-path', '/tmp/tmpv5as26gk']
[2024-02-09T12:38:25.831+0000] {standard_task_runner.py:88} INFO - Job 3509: Subtask data_to_db
[2024-02-09T12:38:25.987+0000] {task_command.py:423} INFO - Running <TaskInstance: Weather_DAG_V2.4.data_to_db scheduled__2024-02-09T01:56:00+00:00 [running]> on host 06573eafe810
[2024-02-09T12:38:26.223+0000] {taskinstance.py:2480} INFO - Exporting env vars: AIRFLOW_CTX_DAG_OWNER='***' AIRFLOW_CTX_DAG_ID='Weather_DAG_V2.4' AIRFLOW_CTX_TASK_ID='data_to_db' AIRFLOW_CTX_EXECUTION_DATE='2024-02-09T01:56:00+00:00' AIRFLOW_CTX_TRY_NUMBER='1' AIRFLOW_CTX_DAG_RUN_ID='scheduled__2024-02-09T01:56:00+00:00'
[2024-02-09T12:38:26.283+0000] {base.py:83} INFO - Using connection ID 'postgres_localhost' for task execution.
[2024-02-09T12:38:26.299+0000] {taskinstance.py:2698} ERROR - Task failed with exception
Traceback (most recent call last):
  File "/home/airflow/.local/lib/python3.8/site-packages/airflow/models/taskinstance.py", line 433, in _execute_task
    result = execute_callable(context=context, **execute_callable_kwargs)
  File "/home/airflow/.local/lib/python3.8/site-packages/airflow/operators/python.py", line 199, in execute
    return_value = self.execute_callable()
  File "/home/airflow/.local/lib/python3.8/site-packages/airflow/operators/python.py", line 216, in execute_callable
    return self.python_callable(*self.op_args, **self.op_kwargs)
  File "/opt/airflow/dags/Weather_dag.py", line 72, in csv_db
    hook.insert_rows(table='weather_tab', rows=CSV_DATA)
  File "/home/airflow/.local/lib/python3.8/site-packages/airflow/providers/common/sql/hooks/sql.py", line 541, in insert_rows
    cur.execute(sql, values)
psycopg2.errors.SyntaxError: INSERT has more expressions than target columns
LINE 1: ... weather_tab  VALUES ('U','n','n','a','m','e','d',':',' ','0...
                                                             ^

[2024-02-09T12:38:26.312+0000] {taskinstance.py:1138} INFO - Marking task as UP_FOR_RETRY. dag_id=Weather_DAG_V2.4, task_id=data_to_db, execution_date=20240209T015600, start_date=20240209T123825, end_date=20240209T123826
[2024-02-09T12:38:26.345+0000] {standard_task_runner.py:107} ERROR - Failed to execute job 3509 for task data_to_db (INSERT has more expressions than target columns
LINE 1: ... weather_tab  VALUES ('U','n','n','a','m','e','d',':',' ','0...
                                                             ^
; 11415)
[2024-02-09T12:38:26.390+0000] {local_task_job_runner.py:234} INFO - Task exited with return code 1
[2024-02-09T12:38:26.533+0000] {taskinstance.py:3280} INFO - 0 downstream tasks scheduled from follow-on schedule check
