[2024-02-13T13:31:01.691+0000] {taskinstance.py:1956} INFO - Dependencies all met for dep_context=non-requeueable deps ti=<TaskInstance: 1Training_DAG_V1.0.get_weather scheduled__2024-02-13T13:26:00+00:00 [queued]>
[2024-02-13T13:31:01.700+0000] {taskinstance.py:1956} INFO - Dependencies all met for dep_context=requeueable deps ti=<TaskInstance: 1Training_DAG_V1.0.get_weather scheduled__2024-02-13T13:26:00+00:00 [queued]>
[2024-02-13T13:31:01.701+0000] {taskinstance.py:2170} INFO - Starting attempt 1 of 1
[2024-02-13T13:31:01.720+0000] {taskinstance.py:2191} INFO - Executing <Task(PythonOperator): get_weather> on 2024-02-13 13:26:00+00:00
[2024-02-13T13:31:01.727+0000] {standard_task_runner.py:60} INFO - Started process 6663 to run task
[2024-02-13T13:31:01.734+0000] {standard_task_runner.py:87} INFO - Running: ['***', 'tasks', 'run', '1Training_DAG_V1.0', 'get_weather', 'scheduled__2024-02-13T13:26:00+00:00', '--job-id', '11618', '--raw', '--subdir', 'DAGS_FOLDER/traning_dag.py', '--cfg-path', '/tmp/tmpdal7vzt3']
[2024-02-13T13:31:01.737+0000] {standard_task_runner.py:88} INFO - Job 11618: Subtask get_weather
[2024-02-13T13:31:01.799+0000] {task_command.py:423} INFO - Running <TaskInstance: 1Training_DAG_V1.0.get_weather scheduled__2024-02-13T13:26:00+00:00 [running]> on host 06573eafe810
[2024-02-13T13:31:01.912+0000] {taskinstance.py:2480} INFO - Exporting env vars: AIRFLOW_CTX_DAG_OWNER='***' AIRFLOW_CTX_DAG_ID='1Training_DAG_V1.0' AIRFLOW_CTX_TASK_ID='get_weather' AIRFLOW_CTX_EXECUTION_DATE='2024-02-13T13:26:00+00:00' AIRFLOW_CTX_TRY_NUMBER='1' AIRFLOW_CTX_DAG_RUN_ID='scheduled__2024-02-13T13:26:00+00:00'
[2024-02-13T13:31:01.919+0000] {taskinstance.py:2698} ERROR - Task failed with exception
Traceback (most recent call last):
  File "/home/airflow/.local/lib/python3.8/site-packages/airflow/models/taskinstance.py", line 433, in _execute_task
    result = execute_callable(context=context, **execute_callable_kwargs)
  File "/home/airflow/.local/lib/python3.8/site-packages/airflow/operators/python.py", line 199, in execute
    return_value = self.execute_callable()
  File "/home/airflow/.local/lib/python3.8/site-packages/airflow/operators/python.py", line 216, in execute_callable
    return self.python_callable(*self.op_args, **self.op_kwargs)
  File "/opt/airflow/dags/traning_dag.py", line 21, in get_weather
    df = pd.read_csv('../For_file/weather.csv')
  File "/home/airflow/.local/lib/python3.8/site-packages/pandas/io/parsers/readers.py", line 912, in read_csv
    return _read(filepath_or_buffer, kwds)
  File "/home/airflow/.local/lib/python3.8/site-packages/pandas/io/parsers/readers.py", line 577, in _read
    parser = TextFileReader(filepath_or_buffer, **kwds)
  File "/home/airflow/.local/lib/python3.8/site-packages/pandas/io/parsers/readers.py", line 1407, in __init__
    self._engine = self._make_engine(f, self.engine)
  File "/home/airflow/.local/lib/python3.8/site-packages/pandas/io/parsers/readers.py", line 1661, in _make_engine
    self.handles = get_handle(
  File "/home/airflow/.local/lib/python3.8/site-packages/pandas/io/common.py", line 859, in get_handle
    handle = open(
FileNotFoundError: [Errno 2] No such file or directory: '../For_file/weather.csv'
[2024-02-13T13:31:01.939+0000] {taskinstance.py:1138} INFO - Marking task as FAILED. dag_id=1Training_DAG_V1.0, task_id=get_weather, execution_date=20240213T132600, start_date=20240213T133101, end_date=20240213T133101
[2024-02-13T13:31:01.962+0000] {standard_task_runner.py:107} ERROR - Failed to execute job 11618 for task get_weather ([Errno 2] No such file or directory: '../For_file/weather.csv'; 6663)
[2024-02-13T13:31:01.987+0000] {local_task_job_runner.py:234} INFO - Task exited with return code 1
[2024-02-13T13:31:02.032+0000] {taskinstance.py:3280} INFO - 0 downstream tasks scheduled from follow-on schedule check
