[2024-02-09T11:02:47.813+0000] {taskinstance.py:1956} INFO - Dependencies all met for dep_context=non-requeueable deps ti=<TaskInstance: Weather_DAG_V2.data_to_db scheduled__2024-02-09T04:16:00+00:00 [queued]>
[2024-02-09T11:02:47.877+0000] {taskinstance.py:1956} INFO - Dependencies all met for dep_context=requeueable deps ti=<TaskInstance: Weather_DAG_V2.data_to_db scheduled__2024-02-09T04:16:00+00:00 [queued]>
[2024-02-09T11:02:47.879+0000] {taskinstance.py:2170} INFO - Starting attempt 2 of 2
[2024-02-09T11:02:47.956+0000] {taskinstance.py:2191} INFO - Executing <Task(PythonOperator): data_to_db> on 2024-02-09 04:16:00+00:00
[2024-02-09T11:02:47.996+0000] {standard_task_runner.py:60} INFO - Started process 6705 to run task
[2024-02-09T11:02:48.016+0000] {standard_task_runner.py:87} INFO - Running: ['***', 'tasks', 'run', 'Weather_DAG_V2', 'data_to_db', 'scheduled__2024-02-09T04:16:00+00:00', '--job-id', '2403', '--raw', '--subdir', 'DAGS_FOLDER/Weather_dag.py', '--cfg-path', '/tmp/tmp2tnuvsvb']
[2024-02-09T11:02:48.019+0000] {standard_task_runner.py:88} INFO - Job 2403: Subtask data_to_db
[2024-02-09T11:02:48.330+0000] {task_command.py:423} INFO - Running <TaskInstance: Weather_DAG_V2.data_to_db scheduled__2024-02-09T04:16:00+00:00 [running]> on host 06573eafe810
[2024-02-09T11:02:48.921+0000] {taskinstance.py:2480} INFO - Exporting env vars: AIRFLOW_CTX_DAG_OWNER='***' AIRFLOW_CTX_DAG_ID='Weather_DAG_V2' AIRFLOW_CTX_TASK_ID='data_to_db' AIRFLOW_CTX_EXECUTION_DATE='2024-02-09T04:16:00+00:00' AIRFLOW_CTX_TRY_NUMBER='2' AIRFLOW_CTX_DAG_RUN_ID='scheduled__2024-02-09T04:16:00+00:00'
[2024-02-09T11:02:48.967+0000] {taskinstance.py:2698} ERROR - Task failed with exception
Traceback (most recent call last):
  File "/home/airflow/.local/lib/python3.8/site-packages/airflow/models/taskinstance.py", line 433, in _execute_task
    result = execute_callable(context=context, **execute_callable_kwargs)
  File "/home/airflow/.local/lib/python3.8/site-packages/airflow/operators/python.py", line 199, in execute
    return_value = self.execute_callable()
  File "/home/airflow/.local/lib/python3.8/site-packages/airflow/operators/python.py", line 216, in execute_callable
    return self.python_callable(*self.op_args, **self.op_kwargs)
  File "/opt/airflow/dags/Weather_dag.py", line 72, in csv_db
    PostgresHook.bulk_load(table=weather_tab, tmp_file=CSV_DATA)
NameError: name 'weather_tab' is not defined
[2024-02-09T11:02:48.990+0000] {taskinstance.py:1138} INFO - Marking task as FAILED. dag_id=Weather_DAG_V2, task_id=data_to_db, execution_date=20240209T041600, start_date=20240209T110247, end_date=20240209T110248
[2024-02-09T11:02:49.074+0000] {standard_task_runner.py:107} ERROR - Failed to execute job 2403 for task data_to_db (name 'weather_tab' is not defined; 6705)
[2024-02-09T11:02:49.121+0000] {local_task_job_runner.py:234} INFO - Task exited with return code 1
[2024-02-09T11:02:49.190+0000] {taskinstance.py:3280} INFO - 0 downstream tasks scheduled from follow-on schedule check
