[2024-03-21T10:19:08.821+0000] {taskinstance.py:1956} INFO - Dependencies all met for dep_context=non-requeueable deps ti=<TaskInstance: mongodb_to_postgres.get_data manual__2024-03-21T10:19:06.010786+00:00 [queued]>
[2024-03-21T10:19:08.834+0000] {taskinstance.py:1956} INFO - Dependencies all met for dep_context=requeueable deps ti=<TaskInstance: mongodb_to_postgres.get_data manual__2024-03-21T10:19:06.010786+00:00 [queued]>
[2024-03-21T10:19:08.835+0000] {taskinstance.py:2170} INFO - Starting attempt 1 of 1
[2024-03-21T10:19:08.855+0000] {taskinstance.py:2191} INFO - Executing <Task(PythonOperator): get_data> on 2024-03-21 10:19:06.010786+00:00
[2024-03-21T10:19:08.862+0000] {standard_task_runner.py:60} INFO - Started process 5596 to run task
[2024-03-21T10:19:08.866+0000] {standard_task_runner.py:87} INFO - Running: ['***', 'tasks', 'run', 'mongodb_to_postgres', 'get_data', 'manual__2024-03-21T10:19:06.010786+00:00', '--job-id', '13937', '--raw', '--subdir', 'DAGS_FOLDER/mongo_dag.py', '--cfg-path', '/tmp/tmptchsbo0u']
[2024-03-21T10:19:08.868+0000] {standard_task_runner.py:88} INFO - Job 13937: Subtask get_data
[2024-03-21T10:19:08.923+0000] {task_command.py:423} INFO - Running <TaskInstance: mongodb_to_postgres.get_data manual__2024-03-21T10:19:06.010786+00:00 [running]> on host 4970cb1bf0e4
[2024-03-21T10:19:09.039+0000] {taskinstance.py:2480} INFO - Exporting env vars: AIRFLOW_CTX_DAG_OWNER='***' AIRFLOW_CTX_DAG_ID='mongodb_to_postgres' AIRFLOW_CTX_TASK_ID='get_data' AIRFLOW_CTX_EXECUTION_DATE='2024-03-21T10:19:06.010786+00:00' AIRFLOW_CTX_TRY_NUMBER='1' AIRFLOW_CTX_DAG_RUN_ID='manual__2024-03-21T10:19:06.010786+00:00'
[2024-03-21T10:19:39.498+0000] {taskinstance.py:2698} ERROR - Task failed with exception
Traceback (most recent call last):
  File "/home/airflow/.local/lib/python3.8/site-packages/airflow/models/taskinstance.py", line 433, in _execute_task
    result = execute_callable(context=context, **execute_callable_kwargs)
  File "/home/airflow/.local/lib/python3.8/site-packages/airflow/operators/python.py", line 199, in execute
    return_value = self.execute_callable()
  File "/home/airflow/.local/lib/python3.8/site-packages/airflow/operators/python.py", line 216, in execute_callable
    return self.python_callable(*self.op_args, **self.op_kwargs)
  File "/opt/airflow/dags/mongo_dag.py", line 24, in get_data
    for doc in data:
  File "/home/airflow/.local/lib/python3.8/site-packages/pymongo/cursor.py", line 1264, in next
    if len(self.__data) or self._refresh():
  File "/home/airflow/.local/lib/python3.8/site-packages/pymongo/cursor.py", line 1155, in _refresh
    self.__session = self.__collection.database.client._ensure_session()
  File "/home/airflow/.local/lib/python3.8/site-packages/pymongo/mongo_client.py", line 1823, in _ensure_session
    return self.__start_session(True, causal_consistency=False)
  File "/home/airflow/.local/lib/python3.8/site-packages/pymongo/mongo_client.py", line 1766, in __start_session
    self._topology._check_implicit_session_support()
  File "/home/airflow/.local/lib/python3.8/site-packages/pymongo/topology.py", line 573, in _check_implicit_session_support
    self._check_session_support()
  File "/home/airflow/.local/lib/python3.8/site-packages/pymongo/topology.py", line 589, in _check_session_support
    self._select_servers_loop(
  File "/home/airflow/.local/lib/python3.8/site-packages/pymongo/topology.py", line 259, in _select_servers_loop
    raise ServerSelectionTimeoutError(
pymongo.errors.ServerSelectionTimeoutError: host.docker.local:27017: [Errno -2] Name or service not known (configured timeouts: socketTimeoutMS: 20000.0ms, connectTimeoutMS: 20000.0ms), Timeout: 30s, Topology Description: <TopologyDescription id: 65fc099db59928372f8c877f, topology_type: Unknown, servers: [<ServerDescription ('host.docker.local', 27017) server_type: Unknown, rtt: None, error=AutoReconnect('host.docker.local:27017: [Errno -2] Name or service not known (configured timeouts: socketTimeoutMS: 20000.0ms, connectTimeoutMS: 20000.0ms)')>]>
[2024-03-21T10:19:39.512+0000] {taskinstance.py:1138} INFO - Marking task as FAILED. dag_id=mongodb_to_postgres, task_id=get_data, execution_date=20240321T101906, start_date=20240321T101908, end_date=20240321T101939
[2024-03-21T10:19:39.529+0000] {standard_task_runner.py:107} ERROR - Failed to execute job 13937 for task get_data (host.docker.local:27017: [Errno -2] Name or service not known (configured timeouts: socketTimeoutMS: 20000.0ms, connectTimeoutMS: 20000.0ms), Timeout: 30s, Topology Description: <TopologyDescription id: 65fc099db59928372f8c877f, topology_type: Unknown, servers: [<ServerDescription ('host.docker.local', 27017) server_type: Unknown, rtt: None, error=AutoReconnect('host.docker.local:27017: [Errno -2] Name or service not known (configured timeouts: socketTimeoutMS: 20000.0ms, connectTimeoutMS: 20000.0ms)')>]>; 5596)
[2024-03-21T10:19:39.561+0000] {local_task_job_runner.py:234} INFO - Task exited with return code 1
[2024-03-21T10:19:39.578+0000] {taskinstance.py:3280} INFO - 0 downstream tasks scheduled from follow-on schedule check
