[2024-02-09T11:21:29.292+0000] {scheduler_job_runner.py:781} ERROR - Executor reports task instance <TaskInstance: Weather_DAG_V5.data_to_db scheduled__2024-02-09T01:11:00+00:00 [queued]> finished (failed) although the task says it's queued. (Info: None) Was the task killed externally?
