[2024-02-12T14:19:05.681+0000] {taskinstance.py:1956} INFO - Dependencies all met for dep_context=non-requeueable deps ti=<TaskInstance: Weather_DAG_V5.0.data_to_db scheduled__2024-02-12T01:01:00+00:00 [queued]>
[2024-02-12T14:19:05.708+0000] {taskinstance.py:1956} INFO - Dependencies all met for dep_context=requeueable deps ti=<TaskInstance: Weather_DAG_V5.0.data_to_db scheduled__2024-02-12T01:01:00+00:00 [queued]>
[2024-02-12T14:19:05.713+0000] {taskinstance.py:2170} INFO - Starting attempt 1 of 1
[2024-02-12T14:19:05.858+0000] {taskinstance.py:2191} INFO - Executing <Task(PythonOperator): data_to_db> on 2024-02-12 01:01:00+00:00
[2024-02-12T14:19:05.873+0000] {standard_task_runner.py:60} INFO - Started process 20308 to run task
[2024-02-12T14:19:05.899+0000] {standard_task_runner.py:87} INFO - Running: ['***', 'tasks', 'run', 'Weather_DAG_V5.0', 'data_to_db', 'scheduled__2024-02-12T01:01:00+00:00', '--job-id', '10747', '--raw', '--subdir', 'DAGS_FOLDER/Weather_dag.py', '--cfg-path', '/tmp/tmprhmylai_']
[2024-02-12T14:19:05.907+0000] {standard_task_runner.py:88} INFO - Job 10747: Subtask data_to_db
[2024-02-12T14:19:06.018+0000] {task_command.py:423} INFO - Running <TaskInstance: Weather_DAG_V5.0.data_to_db scheduled__2024-02-12T01:01:00+00:00 [running]> on host 06573eafe810
[2024-02-12T14:19:06.187+0000] {taskinstance.py:2480} INFO - Exporting env vars: AIRFLOW_CTX_DAG_OWNER='***' AIRFLOW_CTX_DAG_ID='Weather_DAG_V5.0' AIRFLOW_CTX_TASK_ID='data_to_db' AIRFLOW_CTX_EXECUTION_DATE='2024-02-12T01:01:00+00:00' AIRFLOW_CTX_TRY_NUMBER='1' AIRFLOW_CTX_DAG_RUN_ID='scheduled__2024-02-12T01:01:00+00:00'
[2024-02-12T14:19:06.189+0000] {postgres.py:172} INFO - Running copy expert: COPY weather_tab FROM STDIN, filename: weather.csv
[2024-02-12T14:19:06.207+0000] {base.py:83} INFO - Using connection ID 'postgres_localhost' for task execution.
[2024-02-12T14:19:06.238+0000] {taskinstance.py:2698} ERROR - Task failed with exception
Traceback (most recent call last):
  File "/home/airflow/.local/lib/python3.8/site-packages/airflow/models/taskinstance.py", line 433, in _execute_task
    result = execute_callable(context=context, **execute_callable_kwargs)
  File "/home/airflow/.local/lib/python3.8/site-packages/airflow/operators/python.py", line 199, in execute
    return_value = self.execute_callable()
  File "/home/airflow/.local/lib/python3.8/site-packages/airflow/operators/python.py", line 216, in execute_callable
    return self.python_callable(*self.op_args, **self.op_kwargs)
  File "/opt/airflow/dags/Weather_dag.py", line 74, in csv_db
    hook.bulk_load(table='weather_tab', tmp_file=file_name)
  File "/home/airflow/.local/lib/python3.8/site-packages/airflow/providers/postgres/hooks/postgres.py", line 194, in bulk_load
    self.copy_expert(f"COPY {table} FROM STDIN", tmp_file)
  File "/home/airflow/.local/lib/python3.8/site-packages/airflow/providers/postgres/hooks/postgres.py", line 178, in copy_expert
    cur.copy_expert(sql, file)
psycopg2.errors.BadCopyFileFormat: missing data for column "dt"
CONTEXT:  COPY weather_tab, line 1: "Москва,2024-02-12,0,-5,748,1"

[2024-02-12T14:19:06.253+0000] {taskinstance.py:1138} INFO - Marking task as FAILED. dag_id=Weather_DAG_V5.0, task_id=data_to_db, execution_date=20240212T010100, start_date=20240212T141905, end_date=20240212T141906
[2024-02-12T14:19:06.277+0000] {standard_task_runner.py:107} ERROR - Failed to execute job 10747 for task data_to_db (missing data for column "dt"
CONTEXT:  COPY weather_tab, line 1: "Москва,2024-02-12,0,-5,748,1"
; 20308)
[2024-02-12T14:19:06.308+0000] {local_task_job_runner.py:234} INFO - Task exited with return code 1
[2024-02-12T14:19:06.356+0000] {taskinstance.py:3280} INFO - 0 downstream tasks scheduled from follow-on schedule check
