[2024-02-09T11:22:50.081+0000] {taskinstance.py:1956} INFO - Dependencies all met for dep_context=non-requeueable deps ti=<TaskInstance: Weather_DAG_V6.data_to_db scheduled__2024-02-09T00:06:00+00:00 [queued]>
[2024-02-09T11:22:50.106+0000] {taskinstance.py:1956} INFO - Dependencies all met for dep_context=requeueable deps ti=<TaskInstance: Weather_DAG_V6.data_to_db scheduled__2024-02-09T00:06:00+00:00 [queued]>
[2024-02-09T11:22:50.113+0000] {taskinstance.py:2170} INFO - Starting attempt 1 of 2
[2024-02-09T11:22:50.163+0000] {taskinstance.py:2191} INFO - Executing <Task(PythonOperator): data_to_db> on 2024-02-09 00:06:00+00:00
[2024-02-09T11:22:50.170+0000] {standard_task_runner.py:60} INFO - Started process 8193 to run task
[2024-02-09T11:22:50.186+0000] {standard_task_runner.py:87} INFO - Running: ['***', 'tasks', 'run', 'Weather_DAG_V6', 'data_to_db', 'scheduled__2024-02-09T00:06:00+00:00', '--job-id', '2792', '--raw', '--subdir', 'DAGS_FOLDER/Weather_dag.py', '--cfg-path', '/tmp/tmpuo8fzwkz']
[2024-02-09T11:22:50.193+0000] {standard_task_runner.py:88} INFO - Job 2792: Subtask data_to_db
[2024-02-09T11:22:50.318+0000] {task_command.py:423} INFO - Running <TaskInstance: Weather_DAG_V6.data_to_db scheduled__2024-02-09T00:06:00+00:00 [running]> on host 06573eafe810
[2024-02-09T11:22:50.728+0000] {taskinstance.py:2480} INFO - Exporting env vars: AIRFLOW_CTX_DAG_OWNER='***' AIRFLOW_CTX_DAG_ID='Weather_DAG_V6' AIRFLOW_CTX_TASK_ID='data_to_db' AIRFLOW_CTX_EXECUTION_DATE='2024-02-09T00:06:00+00:00' AIRFLOW_CTX_TRY_NUMBER='1' AIRFLOW_CTX_DAG_RUN_ID='scheduled__2024-02-09T00:06:00+00:00'
[2024-02-09T11:22:50.766+0000] {postgres.py:172} INFO - Running copy expert: COPY weather_tab FROM STDIN, filename: <_io.StringIO object at 0x7f7d9875fc10>
[2024-02-09T11:22:50.769+0000] {taskinstance.py:2698} ERROR - Task failed with exception
Traceback (most recent call last):
  File "/home/airflow/.local/lib/python3.8/site-packages/airflow/models/taskinstance.py", line 433, in _execute_task
    result = execute_callable(context=context, **execute_callable_kwargs)
  File "/home/airflow/.local/lib/python3.8/site-packages/airflow/operators/python.py", line 199, in execute
    return_value = self.execute_callable()
  File "/home/airflow/.local/lib/python3.8/site-packages/airflow/operators/python.py", line 216, in execute_callable
    return self.python_callable(*self.op_args, **self.op_kwargs)
  File "/opt/airflow/dags/Weather_dag.py", line 76, in csv_db
    hook.bulk_load(table='weather_tab', tmp_file=buffer)
  File "/home/airflow/.local/lib/python3.8/site-packages/airflow/providers/postgres/hooks/postgres.py", line 194, in bulk_load
    self.copy_expert(f"COPY {table} FROM STDIN", tmp_file)
  File "/home/airflow/.local/lib/python3.8/site-packages/airflow/providers/postgres/hooks/postgres.py", line 173, in copy_expert
    if not os.path.isfile(filename):
  File "/usr/local/lib/python3.8/genericpath.py", line 30, in isfile
    st = os.stat(path)
TypeError: stat: path should be string, bytes, os.PathLike or integer, not _io.StringIO
[2024-02-09T11:22:50.816+0000] {taskinstance.py:1138} INFO - Marking task as UP_FOR_RETRY. dag_id=Weather_DAG_V6, task_id=data_to_db, execution_date=20240209T000600, start_date=20240209T112250, end_date=20240209T112250
[2024-02-09T11:22:50.880+0000] {standard_task_runner.py:107} ERROR - Failed to execute job 2792 for task data_to_db (stat: path should be string, bytes, os.PathLike or integer, not _io.StringIO; 8193)
[2024-02-09T11:22:50.958+0000] {local_task_job_runner.py:234} INFO - Task exited with return code 1
[2024-02-09T11:22:51.124+0000] {taskinstance.py:3280} INFO - 0 downstream tasks scheduled from follow-on schedule check
